I'm sorry, but an uncaught exception occurred.

While running game code:
  File "game/script.rpy", line 351, in script
    $ items.remove(_("key"))
  File "game/script.rpy", line 351, in <module>
    $ items.remove(_("key"))
ValueError: list.remove(x): x not in list

-- Full Traceback ------------------------------------------------------------

Full traceback:
  File "game/script.rpy", line 351, in script
    $ items.remove(_("key"))
  File "/Users/cdean248345/renpy-7.4.11-sdk/renpy/ast.py", line 928, in execute
    renpy.python.py_exec_bytecode(self.code.bytecode, self.hide, store=self.store)
  File "/Users/cdean248345/renpy-7.4.11-sdk/renpy/python.py", line 2245, in py_exec_bytecode
    exec(bytecode, globals, locals)
  File "game/script.rpy", line 351, in <module>
    $ items.remove(_("key"))
  File "/Users/cdean248345/renpy-7.4.11-sdk/renpy/python.py", line 875, in do_mutation
    return method(self, *args, **kwargs)
ValueError: list.remove(x): x not in list

Darwin-21.4.0-x86_64-i386-64bit
Ren'Py 7.4.11.2266
Into the World 1.0
Wed May 18 20:54:01 2022
