I'm sorry, but an uncaught exception occurred.

While running game code:
  File "game/tl/spanish/script.rpy", line 445, in script
    z happy "Bueno, definitivamente fue una aventura extraña, el mundo es un lugar diferente, pero admito que fue muy divertido. ¡Me alegro de que [mascota] esté bien!"
KeyError: u'mascota'

-- Full Traceback ------------------------------------------------------------

Full traceback:
  File "game/tl/spanish/script.rpy", line 445, in script
    z happy "Bueno, definitivamente fue una aventura extraña, el mundo es un lugar diferente, pero admito que fue muy divertido. ¡Me alegro de que [mascota] esté bien!"
  File "renpy/ast.py", line 721, in execute
    renpy.exports.say(who, what, *args, **kwargs)
  File "renpy/exports.py", line 1419, in say
    who(what, *args, **kwargs)
  File "renpy/character.py", line 1236, in __call__
    what = self.prefix_suffix("what", self.what_prefix, what, self.what_suffix)
  File "renpy/character.py", line 1155, in prefix_suffix
    return (sub(prefix) + sub(body) + sub(suffix))
  File "renpy/character.py", line 1135, in sub
    return renpy.substitutions.substitute(s, scope=scope, force=force, translate=translate)[0]
  File "renpy/substitutions.py", line 270, in substitute
    s = formatter.vformat(s, (), kwargs)
  File "/home/tom/ab/renpy-build/tmp/install.linux-x86_64/lib/python2.7/string.py", line 563, in vformat
  File "/home/tom/ab/renpy-build/tmp/install.linux-x86_64/lib/python2.7/string.py", line 585, in _vformat
  File "/home/tom/ab/renpy-build/tmp/install.linux-x86_64/lib/python2.7/string.py", line 646, in get_field
  File "/home/tom/ab/renpy-build/tmp/install.linux-x86_64/lib/python2.7/string.py", line 605, in get_value
KeyError: u'mascota'

Windows-10-10.0.22000
Ren'Py 7.4.11.2266
Into the World 1.0
Thu May 19 14:15:51 2022
